Workbook

Sheet Plot Data
A2: TT | B2: Title | C2: AgQuest Demo Trial
A3: T# | B3: Trial ID | C3: AgQuest
A4: CN | B4: Cooperator
A5: CRA1 | B5: Crop | C5: ALLSA
A6: XL | B6: ARM Pull Flag
A8: 001EID | B8: ARM Column ID | C8: 3 | D8: 6 | E8: 7 | F8: 8 | G8: 9 | H8: 16
A9: 002E~P | B9: Pest Type
A10: 003EPT | B10: Pest Code
A11: 004EPG | B11: Pest Name
A12: 005ECR | B12: Crop Code
A13: 006ECG | B13: Crop Name
A14: 007ECV | B14: Crop Variety
A15: 008ECE | B15: Description
A16: 009EED | B16: Rating Date | C16: 2026-04-02 | D16: 2026-04-10 | E16: 2026-04-15 | F16: 2026-04-23 | H16: 2026-04-02
A17: 010ETD | B17: Rating Time
A18: 011EEV | B18: SE Name | C18: W003 | D18: W001 | E18: CF013 | F18: W003 | H18: W003
A19: 012ECP | B19: Part Rated | C19: PLANT | D19: PLANT | E19: LEAF3 | F19: PLANT | H19: PLANT
A20: 013ERF | B20: Crop or Pest
A21: 014EDT | B21: Rating Type | C21: CONTRO | D21: LODGIN | E21: PESINC | F21: CONTRO | H21: CONTRO
A22: 015ERU | B22: Rating Unit | C22: % | D22: % | E22: % | F22: % | H22: %
A23: 016EBS | B23: Sample Size | C23: 1 | D23: 1 | F23: 1 | H23: 1
A24: 017EBU | B24: Size Unit | C24: PLOT | D24: PLOT | E24: PLOT | F24: PLOT | H24: PLOT
A25: 018EUS | B25: Collect. Basis | C25: 1 | D25: 1 | E25: 1 | F25: 1 | H25: 1
A26: 019EUU | B26: Basis Unit | C26: PLOT | D26: PLOT | E26: PLOT | F26: PLOT | H26: PLOT
A27: 020ERS | B27: Report. Basis | C27: 1 | D27: 1 | E27: 1 | F27: 1 | H27: 1
A28: 021ERN | B28: Basis Unit | C28: PLOT | D28: PLOT | E28: PLOT | F28: PLOT | H28: PLOT
A29: 022ECN | B29: Stage Scale
A30: 023ECS | B30: Crop Stage Maj.
A31: 024ECL | B31: Crop Stage Min.
A32: 025ECX | B32: Crop Stage Max.
A33: 026ECD | B33: Crop Density
A34: 027ECU | B34: Density Unit
A35: 028EPS | B35: Pest Stage Maj.
A36: 029EPL | B36: Pest Stage Min.
A37: 030EPX | B37: Pest Stage Max.
A38: 031EPD | B38: Pest Density
A39: 032EPU | B39: Density Unit
A40: 033EAB | B40: Assessed By
A41: 034EQP | B41: Equipment
A42: 035EET | B42: Rating Timing | C42: A1 | D42: A3 | E42: A9 | F42: A6 | G42: A4 | H42: AA
...

Sheet Treatment Means
A1: Trt | B1: Mean C | C1: StDev C | D1: Mean D | E1: StDev D | F1: Mean E | G1: StDev E | H1: Mean F | I1: StDev F | J1: Mean G | K1: StDev G | L1: Mean H | M1: StDev H
A2: 1 | B2: =AVERAGE('Plot Data'!C49,'Plot Data'!C54,'Plot Data'!C57,'Plot Data'!C62) -> #DIV/0! | C2: =STDEV('Plot Data'!C49,'Plot Data'!C54,'Plot Data'!C57,'Plot Data'!C62) -> #DIV/0! | D2: =AVERAGE('Plot Data'!D49,'Plot Data'!D54,'Plot Data'!D57,'Plot Data'!D62) -> #DIV/0! | E2: =STDEV('Plot Data'!D49,'Plot Data'!D54,'Plot Data'!D57,'Plot Data'!D62) -> #DIV/0! | F2: =AVERAGE('Plot Data'!E49,'Plot Data'!E54,'Plot Data'!E57,'Plot Data'!E62) -> #DIV/0! | G2: =STDEV('Plot Data'!E49,'Plot Data'!E54,'Plot Data'!E57,'Plot Data'!E62) -> #DIV/0! | H2: =AVERAGE('Plot Data'!F49,'Plot Data'!F54,'Plot Data'!F57,'Plot Data'!F62) -> #DIV/0! | I2: =STDEV('Plot Data'!F49,'Plot Data'!F54,'Plot Data'!F57,'Plot Data'!F62) -> #DIV/0! | J2: =AVERAGE('Plot Data'!G49,'Plot Data'!G54,'Plot Data'!G57,'Plot Data'!G62) -> #DIV/0! | K2: =STDEV('Plot Data'!G49,'Plot Data'!G54,'Plot Data'!G57,'Plot Data'!G62) -> #DIV/0! | L2: =AVERAGE('Plot Data'!H49,'Plot Data'!H54,'Plot Data'!H57,'Plot Data'!H62) -> #DIV/0! | M2: =STDEV('Plot Data'!H49,'Plot Data'!H54,'Plot Data'!H57,'Plot Data'!H62) -> #DIV/0!
A3: 2 | B3: =AVERAGE('Plot Data'!C50,'Plot Data'!C53,'Plot Data'!C58,'Plot Data'!C64) -> #DIV/0! | C3: =STDEV('Plot Data'!C50,'Plot Data'!C53,'Plot Data'!C58,'Plot Data'!C64) -> #DIV/0! | D3: =AVERAGE('Plot Data'!D50,'Plot Data'!D53,'Plot Data'!D58,'Plot Data'!D64) -> #DIV/0! | E3: =STDEV('Plot Data'!D50,'Plot Data'!D53,'Plot Data'!D58,'Plot Data'!D64) -> #DIV/0! | F3: =AVERAGE('Plot Data'!E50,'Plot Data'!E53,'Plot Data'!E58,'Plot Data'!E64) -> #DIV/0! | G3: =STDEV('Plot Data'!E50,'Plot Data'!E53,'Plot Data'!E58,'Plot Data'!E64) -> #DIV/0! | H3: =AVERAGE('Plot Data'!F50,'Plot Data'!F53,'Plot Data'!F58,'Plot Data'!F64) -> #DIV/0! | I3: =STDEV('Plot Data'!F50,'Plot Data'!F53,'Plot Data'!F58,'Plot Data'!F64) -> #DIV/0! | J3: =AVERAGE('Plot Data'!G50,'Plot Data'!G53,'Plot Data'!G58,'Plot Data'!G64) -> #DIV/0! | K3: =STDEV('Plot Data'!G50,'Plot Data'!G53,'Plot Data'!G58,'Plot Data'!G64) -> #DIV/0! | L3: =AVERAGE('Plot Data'!H50,'Plot Data'!H53,'Plot Data'!H58,'Plot Data'!H64) -> #DIV/0! | M3: =STDEV('Plot Data'!H50,'Plot Data'!H53,'Plot Data'!H58,'Plot Data'!H64) -> #DIV/0!
A4: 3 | B4: =AVERAGE('Plot Data'!C51,'Plot Data'!C56,'Plot Data'!C59,'Plot Data'!C61) -> #DIV/0! | C4: =STDEV('Plot Data'!C51,'Plot Data'!C56,'Plot Data'!C59,'Plot Data'!C61) -> #DIV/0! | D4: =AVERAGE('Plot Data'!D51,'Plot Data'!D56,'Plot Data'!D59,'Plot Data'!D61) -> #DIV/0! | E4: =STDEV('Plot Data'!D51,'Plot Data'!D56,'Plot Data'!D59,'Plot Data'!D61) -> #DIV/0! | F4: =AVERAGE('Plot Data'!E51,'Plot Data'!E56,'Plot Data'!E59,'Plot Data'!E61) -> #DIV/0! | G4: =STDEV('Plot Data'!E51,'Plot Data'!E56,'Plot Data'!E59,'Plot Data'!E61) -> #DIV/0! | H4: =AVERAGE('Plot Data'!F51,'Plot Data'!F56,'Plot Data'!F59,'Plot Data'!F61) -> #DIV/0! | I4: =STDEV('Plot Data'!F51,'Plot Data'!F56,'Plot Data'!F59,'Plot Data'!F61) -> #DIV/0! | J4: =AVERAGE('Plot Data'!G51,'Plot Data'!G56,'Plot Data'!G59,'Plot Data'!G61) -> #DIV/0! | K4: =STDEV('Plot Data'!G51,'Plot Data'!G56,'Plot Data'!G59,'Plot Data'!G61) -> #DIV/0! | L4: =AVERAGE('Plot Data'!H51,'Plot Data'!H56,'Plot Data'!H59,'Plot Data'!H61) -> #DIV/0! | M4: =STDEV('Plot Data'!H51,'Plot Data'!H56,'Plot Data'!H59,'Plot Data'!H61) -> #DIV/0!
A5: 4 | B5: =AVERAGE('Plot Data'!C52,'Plot Data'!C55,'Plot Data'!C60,'Plot Data'!C63) -> #DIV/0! | C5: =STDEV('Plot Data'!C52,'Plot Data'!C55,'Plot Data'!C60,'Plot Data'!C63) -> #DIV/0! | D5: =AVERAGE('Plot Data'!D52,'Plot Data'!D55,'Plot Data'!D60,'Plot Data'!D63) -> #DIV/0! | E5: =STDEV('Plot Data'!D52,'Plot Data'!D55,'Plot Data'!D60,'Plot Data'!D63) -> #DIV/0! | F5: =AVERAGE('Plot Data'!E52,'Plot Data'!E55,'Plot Data'!E60,'Plot Data'!E63) -> #DIV/0! | G5: =STDEV('Plot Data'!E52,'Plot Data'!E55,'Plot Data'!E60,'Plot Data'!E63) -> #DIV/0! | H5: =AVERAGE('Plot Data'!F52,'Plot Data'!F55,'Plot Data'!F60,'Plot Data'!F63) -> #DIV/0! | I5: =STDEV('Plot Data'!F52,'Plot Data'!F55,'Plot Data'!F60,'Plot Data'!F63) -> #DIV/0! | J5: =AVERAGE('Plot Data'!G52,'Plot Data'!G55,'Plot Data'!G60,'Plot Data'!G63) -> #DIV/0! | K5: =STDEV('Plot Data'!G52,'Plot Data'!G55,'Plot Data'!G60,'Plot Data'!G63) -> #DIV/0! | L5: =AVERAGE('Plot Data'!H52,'Plot Data'!H55,'Plot Data'!H60,'Plot Data'!H63) -> #DIV/0! | M5: =STDEV('Plot Data'!H52,'Plot Data'!H55,'Plot Data'!H60,'Plot Data'!H63) -> #DIV/0!

Sheet Subsample Plot Data
A1: 001EID | B1: ARM Column ID | C1: 3 | D1: 6 | E1: 7 | F1: 8 | G1: 9 | H1: 16
A2: 002E~P | B2: Pest Type
A3: 003EPT | B3: Pest Code
A4: 004EPG | B4: Pest Name
A5: 005ECR | B5: Crop Code
A6: 006ECG | B6: Crop Name
A7: 007ECV | B7: Crop Variety
A8: 008ECE | B8: Description
A9: 009EED | B9: Rating Date | C9: 2026-04-02 | D9: 2026-04-10 | E9: 2026-04-15 | F9: 2026-04-23 | H9: 2026-04-02
A10: 010ETD | B10: Rating Time
A11: 011EEV | B11: SE Name | C11: W003 | D11: W001 | E11: CF013 | F11: W003 | H11: W003
A12: 012ECP | B12: Part Rated | C12: PLANT | D12: PLANT | E12: LEAF3 | F12: PLANT | H12: PLANT
A13: 013ERF | B13: Crop or Pest
A14: 014EDT | B14: Rating Type | C14: CONTRO | D14: LODGIN | E14: PESINC | F14: CONTRO | H14: CONTRO
A15: 015ERU | B15: Rating Unit | C15: % | D15: % | E15: % | F15: % | H15: %
A16: 016EBS | B16: Sample Size | C16: 1 | D16: 1 | F16: 1 | H16: 1
A17: 017EBU | B17: Size Unit | C17: PLOT | D17: PLOT | E17: PLOT | F17: PLOT | H17: PLOT
A18: 018EUS | B18: Collect. Basis | C18: 1 | D18: 1 | E18: 1 | F18: 1 | H18: 1
A19: 019EUU | B19: Basis Unit | C19: PLOT | D19: PLOT | E19: PLOT | F19: PLOT | H19: PLOT
A20: 020ERS | B20: Report. Basis | C20: 1 | D20: 1 | E20: 1 | F20: 1 | H20: 1
A21: 021ERN | B21: Basis Unit | C21: PLOT | D21: PLOT | E21: PLOT | F21: PLOT | H21: PLOT
A22: 022ECN | B22: Stage Scale
A23: 023ECS | B23: Crop Stage Maj.
A24: 024ECL | B24: Crop Stage Min.
A25: 025ECX | B25: Crop Stage Max.
A26: 026ECD | B26: Crop Density
A27: 027ECU | B27: Density Unit
A28: 028EPS | B28: Pest Stage Maj.
A29: 029EPL | B29: Pest Stage Min.
A30: 030EPX | B30: Pest Stage Max.
A31: 031EPD | B31: Pest Density
A32: 032EPU | B32: Density Unit
A33: 033EAB | B33: Assessed By
A34: 034EQP | B34: Equipment
A35: 035EET | B35: Rating Timing | C35: A1 | D35: A3 | E35: A9 | F35: A6 | G35: A4 | H35: AA
A36: 036ETI | B36: Trt-Eval Interval | C36: -28 DA-A | D36: -20 DA-A | E36: -15 DA-A | F36: -7 DA-A | H36: -28 DA-A
A37: 037EPI | B37: Plant-Eval Interval | C37: -7 DP-1 | D37: 1 DP-1 | E37: 6 DP-1 | F37: 14 DP-1 | H37: -7 DP-1
A38: 038EUT | B38: Untrt.RatingType
A39: 039EDP | B39: ARM Actions
A40: 040ENS | B40: # Subsamples | C40: 1 | D40: 1 | E40: 1 | F40: 1 | G40: 1 | H40: 1
...

Sheet Subsample Treatment Means
A1: Trt | B1: Mean C | C1: StDev C | D1: Mean D | E1: StDev D | F1: Mean E | G1: StDev E | H1: Mean F | I1: StDev F | J1: Mean G | K1: StDev G | L1: Mean H | M1: StDev H
A2: 1 | B2: =AVERAGE('Subsample Plot Data'!C42,'Subsample Plot Data'!C47,'Subsample Plot Data'!C50,'Subsample Plot Data'!C55) -> #DIV/0! | C2: =STDEV('Subsample Plot Data'!C42,'Subsample Plot Data'!C47,'Subsample Plot Data'!C50,'Subsample Plot Data'!C55) -> #DIV/0! | D2: =AVERAGE('Subsample Plot Data'!D42,'Subsample Plot Data'!D47,'Subsample Plot Data'!D50,'Subsample Plot Data'!D55) -> #DIV/0! | E2: =STDEV('Subsample Plot Data'!D42,'Subsample Plot Data'!D47,'Subsample Plot Data'!D50,'Subsample Plot Data'!D55) -> #DIV/0! | F2: =AVERAGE('Subsample Plot Data'!E42,'Subsample Plot Data'!E47,'Subsample Plot Data'!E50,'Subsample Plot Data'!E55) -> #DIV/0! | G2: =STDEV('Subsample Plot Data'!E42,'Subsample Plot Data'!E47,'Subsample Plot Data'!E50,'Subsample Plot Data'!E55) -> #DIV/0! | H2: =AVERAGE('Subsample Plot Data'!F42,'Subsample Plot Data'!F47,'Subsample Plot Data'!F50,'Subsample Plot Data'!F55) -> #DIV/0! | I2: =STDEV('Subsample Plot Data'!F42,'Subsample Plot Data'!F47,'Subsample Plot Data'!F50,'Subsample Plot Data'!F55) -> #DIV/0! | J2: =AVERAGE('Subsample Plot Data'!G42,'Subsample Plot Data'!G47,'Subsample Plot Data'!G50,'Subsample Plot Data'!G55) -> #DIV/0! | K2: =STDEV('Subsample Plot Data'!G42,'Subsample Plot Data'!G47,'Subsample Plot Data'!G50,'Subsample Plot Data'!G55) -> #DIV/0! | L2: =AVERAGE('Subsample Plot Data'!H42,'Subsample Plot Data'!H47,'Subsample Plot Data'!H50,'Subsample Plot Data'!H55) -> #DIV/0! | M2: =STDEV('Subsample Plot Data'!H42,'Subsample Plot Data'!H47,'Subsample Plot Data'!H50,'Subsample Plot Data'!H55) -> #DIV/0!
A3: 2 | B3: =AVERAGE('Subsample Plot Data'!C43,'Subsample Plot Data'!C46,'Subsample Plot Data'!C51,'Subsample Plot Data'!C57) -> #DIV/0! | C3: =STDEV('Subsample Plot Data'!C43,'Subsample Plot Data'!C46,'Subsample Plot Data'!C51,'Subsample Plot Data'!C57) -> #DIV/0! | D3: =AVERAGE('Subsample Plot Data'!D43,'Subsample Plot Data'!D46,'Subsample Plot Data'!D51,'Subsample Plot Data'!D57) -> #DIV/0! | E3: =STDEV('Subsample Plot Data'!D43,'Subsample Plot Data'!D46,'Subsample Plot Data'!D51,'Subsample Plot Data'!D57) -> #DIV/0! | F3: =AVERAGE('Subsample Plot Data'!E43,'Subsample Plot Data'!E46,'Subsample Plot Data'!E51,'Subsample Plot Data'!E57) -> #DIV/0! | G3: =STDEV('Subsample Plot Data'!E43,'Subsample Plot Data'!E46,'Subsample Plot Data'!E51,'Subsample Plot Data'!E57) -> #DIV/0! | H3: =AVERAGE('Subsample Plot Data'!F43,'Subsample Plot Data'!F46,'Subsample Plot Data'!F51,'Subsample Plot Data'!F57) -> #DIV/0! | I3: =STDEV('Subsample Plot Data'!F43,'Subsample Plot Data'!F46,'Subsample Plot Data'!F51,'Subsample Plot Data'!F57) -> #DIV/0! | J3: =AVERAGE('Subsample Plot Data'!G43,'Subsample Plot Data'!G46,'Subsample Plot Data'!G51,'Subsample Plot Data'!G57) -> #DIV/0! | K3: =STDEV('Subsample Plot Data'!G43,'Subsample Plot Data'!G46,'Subsample Plot Data'!G51,'Subsample Plot Data'!G57) -> #DIV/0! | L3: =AVERAGE('Subsample Plot Data'!H43,'Subsample Plot Data'!H46,'Subsample Plot Data'!H51,'Subsample Plot Data'!H57) -> #DIV/0! | M3: =STDEV('Subsample Plot Data'!H43,'Subsample Plot Data'!H46,'Subsample Plot Data'!H51,'Subsample Plot Data'!H57) -> #DIV/0!
A4: 3 | B4: =AVERAGE('Subsample Plot Data'!C44,'Subsample Plot Data'!C49,'Subsample Plot Data'!C52,'Subsample Plot Data'!C54) -> #DIV/0! | C4: =STDEV('Subsample Plot Data'!C44,'Subsample Plot Data'!C49,'Subsample Plot Data'!C52,'Subsample Plot Data'!C54) -> #DIV/0! | D4: =AVERAGE('Subsample Plot Data'!D44,'Subsample Plot Data'!D49,'Subsample Plot Data'!D52,'Subsample Plot Data'!D54) -> #DIV/0! | E4: =STDEV('Subsample Plot Data'!D44,'Subsample Plot Data'!D49,'Subsample Plot Data'!D52,'Subsample Plot Data'!D54) -> #DIV/0! | F4: =AVERAGE('Subsample Plot Data'!E44,'Subsample Plot Data'!E49,'Subsample Plot Data'!E52,'Subsample Plot Data'!E54) -> #DIV/0! | G4: =STDEV('Subsample Plot Data'!E44,'Subsample Plot Data'!E49,'Subsample Plot Data'!E52,'Subsample Plot Data'!E54) -> #DIV/0! | H4: =AVERAGE('Subsample Plot Data'!F44,'Subsample Plot Data'!F49,'Subsample Plot Data'!F52,'Subsample Plot Data'!F54) -> #DIV/0! | I4: =STDEV('Subsample Plot Data'!F44,'Subsample Plot Data'!F49,'Subsample Plot Data'!F52,'Subsample Plot Data'!F54) -> #DIV/0! | J4: =AVERAGE('Subsample Plot Data'!G44,'Subsample Plot Data'!G49,'Subsample Plot Data'!G52,'Subsample Plot Data'!G54) -> #DIV/0! | K4: =STDEV('Subsample Plot Data'!G44,'Subsample Plot Data'!G49,'Subsample Plot Data'!G52,'Subsample Plot Data'!G54) -> #DIV/0! | L4: =AVERAGE('Subsample Plot Data'!H44,'Subsample Plot Data'!H49,'Subsample Plot Data'!H52,'Subsample Plot Data'!H54) -> #DIV/0! | M4: =STDEV('Subsample Plot Data'!H44,'Subsample Plot Data'!H49,'Subsample Plot Data'!H52,'Subsample Plot Data'!H54) -> #DIV/0!
A5: 4 | B5: =AVERAGE('Subsample Plot Data'!C45,'Subsample Plot Data'!C48,'Subsample Plot Data'!C53,'Subsample Plot Data'!C56) -> #DIV/0! | C5: =STDEV('Subsample Plot Data'!C45,'Subsample Plot Data'!C48,'Subsample Plot Data'!C53,'Subsample Plot Data'!C56) -> #DIV/0! | D5: =AVERAGE('Subsample Plot Data'!D45,'Subsample Plot Data'!D48,'Subsample Plot Data'!D53,'Subsample Plot Data'!D56) -> #DIV/0! | E5: =STDEV('Subsample Plot Data'!D45,'Subsample Plot Data'!D48,'Subsample Plot Data'!D53,'Subsample Plot Data'!D56) -> #DIV/0! | F5: =AVERAGE('Subsample Plot Data'!E45,'Subsample Plot Data'!E48,'Subsample Plot Data'!E53,'Subsample Plot Data'!E56) -> #DIV/0! | G5: =STDEV('Subsample Plot Data'!E45,'Subsample Plot Data'!E48,'Subsample Plot Data'!E53,'Subsample Plot Data'!E56) -> #DIV/0! | H5: =AVERAGE('Subsample Plot Data'!F45,'Subsample Plot Data'!F48,'Subsample Plot Data'!F53,'Subsample Plot Data'!F56) -> #DIV/0! | I5: =STDEV('Subsample Plot Data'!F45,'Subsample Plot Data'!F48,'Subsample Plot Data'!F53,'Subsample Plot Data'!F56) -> #DIV/0! | J5: =AVERAGE('Subsample Plot Data'!G45,'Subsample Plot Data'!G48,'Subsample Plot Data'!G53,'Subsample Plot Data'!G56) -> #DIV/0! | K5: =STDEV('Subsample Plot Data'!G45,'Subsample Plot Data'!G48,'Subsample Plot Data'!G53,'Subsample Plot Data'!G56) -> #DIV/0! | L5: =AVERAGE('Subsample Plot Data'!H45,'Subsample Plot Data'!H48,'Subsample Plot Data'!H53,'Subsample Plot Data'!H56) -> #DIV/0! | M5: =STDEV('Subsample Plot Data'!H45,'Subsample Plot Data'!H48,'Subsample Plot Data'!H53,'Subsample Plot Data'!H56) -> #DIV/0!

Sheet Applications
A1: ADA | B1: Application Date
A2: ATA | B2: Start Time
A3: FIA | B3: Stop Time
A4: IJA | B4: Interval to Prev. Appl.
A5: IKA | B5: Interval Unit
A6: AOA | B6: Appl. Method
A7: ANA | B7: Appl. Timing
A8: AMA | B8: Appl. Placement
A9: AEA | B9: Applied By
A10: AIA | B10: Air Temp. Start
A11: ^AA | B11: Air Temp. Stop
A12: TEA | B12: Air Temp. Unit
... A79: TMA | B79: Tank Mix (Y/N)

Sheet Comments
B1: Enter all comments in cell below:
A2: ECM

Sheet Treatments
A1: Trt | C1: Treatment | D1: Form | E1: Form | F1: Form | H1: Rate
A2: No. | B2: Type | C2: Name | D2: Conc | E2: Unit | F2: Type | G2: Rate | H2: Unit
A3: 1 | B3: CHK
A4: 2 | B4: FUNG | C4: APRON | D4: 25 | E4: %W/W | F4: W | G4: 5 | H4: % w/v
A5: 3 | B5: HERB | C5: AAtrex-WP | D5: 80 | E5: %AW/W | F5: WP | G5: 10 | H5: % w/v
A6: 4 | B6: HERB | C6: Banvel 720 | D6: 2.9 | E6: LBA/GAL | F6: L | G6: 8 | H6: % v/v
